Workbook
Name Argentina: #REF!
Name España: #REF!
Name México: #REF!

Sheet Definicion de estructura OITM
A1: Campo | B1: Descripción | C1: Tbl
A2: SCHEMA_NAME | B2: Esquema en el que está la tabla (EMPAQPLAST_PROD). | C2: OITM
A3: TABLE_NAME | B3: Nombre de la tabla (OITM). | C3: OITM
A4: TABLE_OID | B4: Identificador interno de la tabla en HANA. | C4: OITM
A5: COLUMN_NAME | B5: Nombre del campo en la tabla. | C5: OITM
A6: POSITION | B6: Posición ordinal del campo dentro de la tabla. | C6: OITM
A7: DATA_TYPE_ID | B7: Identificador interno del tipo de dato en HANA. | C7: OITM
A8: DATA_TYPE_NAME | B8: Tipo de dato (ej. NVARCHAR, DECIMAL, INTEGER). | C8: OITM
A9: OFFSET | B9: Desplazamiento en memoria del campo dentro del registro. | C9: OITM
A10: LENGTH | B10: Longitud máxima (ej. 50 para NVARCHAR(50)). | C10: OITM
A11: SCALE | B11: Precisión de decimales (para DECIMAL, NUMERIC). | C11: OITM
A12: IS_NULLABLE | B12: Indica si el campo puede ser NULL (Y/N). | C12: OITM
... A43: NUMA_NODE_INDEXES | B43: Asignación de índices en NUMA. | C43: OITM

Sheet Inventario Campos OITM
A1: SCHEMA_NAME | B1: TABLE_NAME | C1: TABLE_OID | D1: COLUMN_NAME | E1: POSITION | F1: DATA_TYPE_ID | G1: DATA_TYPE_NAME | H1: OFFSET | I1: LENGTH | J1: SCALE | K1: IS_NULLABLE | L1: DEFAULT_VALUE | M1: COLLATION | N1: COMMENTS | O1: MAX_VALUE | P1: MIN_VALUE | Q1: CS_DATA_TYPE_ID | R1: CS_DATA_TYPE_NAME | S1: DDIC_DATA_TYPE_ID | T1: DDIC_DATA_TYPE_NAME | U1: COMPRESSION_TYPE | V1: INDEX_TYPE | W1: COLUMN_ID | X1: PRELOAD | Y1: GENERATED_ALWAYS_AS | Z1: HAS_SCHEMA_FLEXIBILITY | AA1: FUZZY_SEARCH_INDEX | AB1: FUZZY_SEARCH_MODE | AC1: MEMORY_THRESHOLD | AD1: LOAD_UNIT | AE1: GENERATION_TYPE | AF1: IS_CACHABLE | AG1: IS_CACHE_KEY | AH1: ROW_ORDER_POSITION | AI1: IS_HIDDEN | AJ1: IS_MASKED | AK1: MASK_EXPRESSION | AL1: CLIENTSIDE_ENCRYPTION_STATUS | AM1: CLIENTSIDE_ENCRYPTION_COLUMN_KEY_ID | AN1: CLIENTSIDE_ENCRYPTION_MODE | AO1: PERSISTENT_MEMORY | AP1: NUMA_NODE_INDEXES
A2: EMPAQPLAST_PROD | B2: OITM | C2: 1535248 | D2: AcqDate | E2: 277 | F2: 93 | G2: TIMESTAMP | H2: 904 | I2: 27 | J2: 7 | K2: TRUE | Q2: 64 | R2: LONGDATE | S2: 32 | T2: INVALID | U2: DEFAULT | V2: NONE | W2: 1535525 | X2: TRUE | Z2: FALSE | AA2: FALSE | AD2: DEFAULT | AF2: FALSE | AG2: FALSE | AI2: FALSE | AJ2: FALSE
A3: EMPAQPLAST_PROD | B3: OITM | C3: 1535248 | D3: AssblValue | E3: 247 | F3: 3 | G3: DECIMAL | H3: 786 | I3: 21 | J3: 6 | K3: TRUE | Q3: 66 | R3: FIXED | S3: 32 | T3: INVALID | U3: DEFAULT | V3: NONE | W3: 1535495 | X3: TRUE | Z3: FALSE | AA3: FALSE | AD3: DEFAULT | AF3: FALSE | AG3: FALSE | AI3: FALSE | AJ3: FALSE
A4: EMPAQPLAST_PROD | B4: OITM | C4: 1535248 | D4: AssetAmnt1 | E4: 284 | F4: 3 | G4: DECIMAL | H4: 920 | I4: 21 | J4: 6 | K4: TRUE | Q4: 66 | R4: FIXED | S4: 32 | T4: INVALID | U4: DEFAULT | V4: NONE | W4: 1535532 | X4: TRUE | Z4: FALSE | AA4: FALSE | AD4: DEFAULT | AF4: FALSE | AG4: FALSE | AI4: FALSE | AJ4: FALSE
A5: EMPAQPLAST_PROD | B5: OITM | C5: 1535248 | D5: AssetAmnt2 | E5: 285 | F5: 3 | G5: DECIMAL | H5: 930 | I5: 21 | J5: 6 | K5: TRUE | Q5: 66 | R5: FIXED | S5: 32 | T5: INVALID | U5: DEFAULT | V5: NONE | W5: 1535533 | X5: TRUE | Z5: FALSE | AA5: FALSE | AD5: DEFAULT | AF5: FALSE | AG5: FALSE | AI5: FALSE | AJ5: FALSE
A6: EMPAQPLAST_PROD | B6: OITM | C6: 1535248 | D6: AssetClass | E6: 266 | F6: -9 | G6: NVARCHAR | H6: 1776 | I6: 20 | K6: TRUE | Q6: 83 | R6: STRING | S6: 32 | T6: INVALID | U6: DEFAULT | V6: NONE | W6: 1535514 | X6: TRUE | Z6: FALSE | AA6: FALSE | AD6: DEFAULT | AF6: FALSE | AG6: FALSE | AI6: FALSE | AJ6: FALSE
A7: EMPAQPLAST_PROD | B7: OITM | C7: 1535248 | D7: AssetGroup | E7: 267 | F7: -9 | G7: NVARCHAR | H7: 1776 | I7: 15 | K7: TRUE | Q7: 83 | R7: STRING | S7: 32 | T7: INVALID | U7: DEFAULT | V7: NONE | W7: 1535515 | X7: TRUE | Z7: FALSE | AA7: FALSE | AD7: DEFAULT | AF7: FALSE | AG7: FALSE | AI7: FALSE | AJ7: FALSE
A8: EMPAQPLAST_PROD | B8: OITM | C8: 1535248 | D8: AssetItem | E8: 60 | F8: -9 | G8: NVARCHAR | H8: 1568 | I8: 1 | K8: TRUE | L8: N | Q8: 83 | R8: STRING | S8: 32 | T8: INVALID | U8: DEFAULT | V8: NONE | W8: 1535308 | X8: TRUE | Z8: FALSE | AA8: FALSE | AD8: DEFAULT | AF8: FALSE | AG8: FALSE | AI8: FALSE | AJ8: FALSE
A9: EMPAQPLAST_PROD | B9: OITM | C9: 1535248 | D9: AssetRmk1 | E9: 282 | F9: -9 | G9: NVARCHAR | H9: 1776 | I9: 100 | K9: TRUE | Q9: 83 | R9: STRING | S9: 32 | T9: INVALID | U9: DEFAULT | V9: NONE | W9: 1535530 | X9: TRUE | Z9: FALSE | AA9: FALSE | AD9: DEFAULT | AF9: FALSE | AG9: FALSE | AI9: FALSE | AJ9: FALSE
A10: EMPAQPLAST_PROD | B10: OITM | C10: 1535248 | D10: AssetRmk2 | E10: 283 | F10: -9 | G10: NVARCHAR | H10: 1776 | I10: 100 | K10: TRUE | Q10: 83 | R10: STRING | S10: 32 | T10: INVALID | U10: DEFAULT | V10: NONE | W10: 1535531 | X10: TRUE | Z10: FALSE | AA10: FALSE | AD10: DEFAULT | AF10: FALSE | AG10: FALSE | AI10: FALSE | AJ10: FALSE
A11: EMPAQPLAST_PROD | B11: OITM | C11: 1535248 | D11: AssetSerNo | E11: 287 | F11: -9 | G11: NVARCHAR | H11: 1776 | I11: 32 | K11: TRUE | Q11: 83 | R11: STRING | S11: 32 | T11: INVALID | U11: DEFAULT | V11: NONE | W11: 1535535 | X11: TRUE | Z11: FALSE | AA11: FALSE | AD11: DEFAULT | AF11: FALSE | AG11: FALSE | AI11: FALSE | AJ11: FALSE
A12: EMPAQPLAST_PROD | B12: OITM | C12: 1535248 | D12: AsstStatus | E12: 275 | F12: -9 | G12: NVARCHAR | H12: 1776 | I12: 1 | K12: TRUE | L12: N | Q12: 83 | R12: STRING | S12: 32 | T12: INVALID | U12: DEFAULT | V12: NONE | W12: 1535523 | X12: TRUE | Z12: FALSE | AA12: FALSE | AD12: DEFAULT | AF12: FALSE | AG12: FALSE | AI12: FALSE | AJ12: FALSE
A13: EMPAQPLAST_PROD | B13: OITM | C13: 1535248 | D13: AssVal4WTR | E13: 314 | F13: 3 | G13: DECIMAL | H13: 1031 | I13: 21 | J13: 6 | K13: TRUE | Q13: 66 | R13: FIXED | S13: 32 | T13: INVALID | U13: DEFAULT | V13: NONE | W13: 1535562 | X13: TRUE | Z13: FALSE | AA13: FALSE | AD13: DEFAULT | AF13: FALSE | AG13: FALSE | AI13: FALSE | AJ13: FALSE
A14: EMPAQPLAST_PROD | B14: OITM | C14: 1535248 | D14: AtcEntry | E14: 259 | F14: 4 | G14: INTEGER | H14: 848 | I14: 10 | J14: 0 | K14: TRUE | Q14: 73 | R14: INT | S14: 32 | T14: INVALID | U14: DEFAULT | V14: NONE | W14: 1535507 | X14: TRUE | Z14: FALSE | AA14: FALSE | AD14: DEFAULT | AF14: FALSE | AG14: FALSE | AI14: FALSE | AJ14: FALSE
A15: EMPAQPLAST_PROD | B15: OITM | C15: 1535248 | D15: Attachment | E15: 258 | F15: -10 | G15: NCLOB | H15: 824 | I15: 2147483647 | K15: TRUE | Q15: 89 | R15: LOB | S15: 32 | T15: INVALID | U15: DEFAULT | V15: NONE | W15: 1535506 | X15: TRUE | Z15: FALSE | AA15: FALSE | AC15: 1000 | AD15: DEFAULT | AF15: FALSE | AG15: FALSE | AI15: FALSE | AJ15: FALSE
A16: EMPAQPLAST_PROD | B16: OITM | C16: 1535248 | D16: AutoBatch | E16: 321 | F16: -9 | G16: NVARCHAR | H16: 1776 | I16: 1 | K16: TRUE | L16: N | Q16: 83 | R16: STRING | S16: 32 | T16: INVALID | U16: DEFAULT | V16: NONE | W16: 1535569 | X16: TRUE | Z16: FALSE | AA16: FALSE | AD16: DEFAULT | AF16: FALSE | AG16: FALSE | AI16: FALSE | AJ16: FALSE
A17: EMPAQPLAST_PROD | B17: OITM | C17: 1535248 | D17: AvgPrice | E17: 180 | F17: 3 | G17: DECIMAL | H17: 608 | I17: 21 | J17: 6 | K17: TRUE | Q17: 66 | R17: FIXED | S17: 32 | T17: INVALID | U17: DEFAULT | V17: NONE | W17: 1535428 | X17: TRUE | Z17: FALSE | AA17: FALSE | AD17: DEFAULT | AF17: FALSE | AG17: FALSE | AI17: FALSE | AJ17: FALSE
A18: EMPAQPLAST_PROD | B18: OITM | C18: 1535248 | D18: BaseUnit | E18: 215 | F18: -9 | G18: NVARCHAR | H18: 1776 | I18: 20 | K18: TRUE | Q18: 83 | R18: STRING | S18: 32 | T18: INVALID | U18: DEFAULT | V18: NONE | W18: 1535463 | X18: TRUE | Z18: FALSE | AA18: FALSE | AD18: DEFAULT | AF18: FALSE | AG18: FALSE | AI18: FALSE | AJ18: FALSE
A19: EMPAQPLAST_PROD | B19: OITM | C19: 1535248 | D19: BeverGrpC | E19: 256 | F19: -9 | G19: NVARCHAR | H19: 1776 | I19: 2 | K19: TRUE | Q19: 83 | R19: STRING | S19: 32 | T19: INVALID | U19: DEFAULT | V19: NONE | W19: 1535504 | X19: TRUE | Z19: FALSE | AA19: FALSE | AD19: DEFAULT | AF19: FALSE | AG19: FALSE | AI19: FALSE | AJ19: FALSE
A20: EMPAQPLAST_PROD | B20: OITM | C20: 1535248 | D20: BeverTblC | E20: 255 | F20: -9 | G20: NVARCHAR | H20: 1776 | I20: 2 | K20: TRUE | Q20: 83 | R20: STRING | S20: 32 | T20: INVALID | U20: DEFAULT | V20: NONE | W20: 1535503 | X20: TRUE | Z20: FALSE | AA20: FALSE | AD20: DEFAULT | AF20: FALSE | AG20: FALSE | AI20: FALSE | AJ20: FALSE
A21: EMPAQPLAST_PROD | B21: OITM | C21: 1535248 | D21: BeverTM | E21: 257 | F21: 4 | G21: INTEGER | H21: 819 | I21: 10 | J21: 0 | K21: TRUE | L21: -1 | Q21: 73 | R21: INT | S21: 32 | T21: INVALID | U21: DEFAULT | V21: NONE | W21: 1535505 | X21: TRUE | Z21: FALSE | AA21: FALSE | AD21: DEFAULT | AF21: FALSE | AG21: FALSE | AI21: FALSE | AJ21: FALSE
A22: EMPAQPLAST_PROD | B22: OITM | C22: 1535248 | D22: BHeight1 | E22: 81 | F22: 3 | G22: DECIMAL | H22: 383 | I22: 21 | J22: 6 | K22: TRUE | Q22: 66 | R22: FIXED | S22: 32 | T22: INVALID | U22: DEFAULT | V22: NONE | W22: 1535329 | X22: TRUE | Z22: FALSE | AA22: FALSE | AD22: DEFAULT | AF22: FALSE | AG22: FALSE | AI22: FALSE | AJ22: FALSE
A23: EMPAQPLAST_PROD | B23: OITM | C23: 1535248 | D23: BHeight2 | E23: 83 | F23: 3 | G23: DECIMAL | H23: 396 | I23: 21 | J23: 6 | K23: TRUE | Q23: 66 | R23: FIXED | S23: 32 | T23: INVALID | U23: DEFAULT | V23: NONE | W23: 1535331 | X23: TRUE | Z23: FALSE | AA23: FALSE | AD23: DEFAULT | AF23: FALSE | AG23: FALSE | AI23: FALSE | AJ23: FALSE
A24: EMPAQPLAST_PROD | B24: OITM | C24: 1535248 | D24: BHght1Unit | E24: 82 | F24: 5 | G24: SMALLINT | H24: 393 | I24: 5 | J24: 0 | K24: TRUE | Q24: 73 | R24: INT | S24: 32 | T24: INVALID | U24: DEFAULT | V24: NONE | W24: 1535330 | X24: TRUE | Z24: FALSE | AA24: FALSE | AD24: DEFAULT | AF24: FALSE | AG24: FALSE | AI24: FALSE | AJ24: FALSE
A25: EMPAQPLAST_PROD | B25: OITM | C25: 1535248 | D25: BHght2Unit | E25: 84 | F25: 5 | G25: SMALLINT | H25: 406 | I25: 5 | J25: 0 | K25: TRUE | Q25: 73 | R25: INT | S25: 32 | T25: INVALID | U25: DEFAULT | V25: NONE | W25: 1535332 | X25: TRUE | Z25: FALSE | AA25: FALSE | AD25: DEFAULT | AF25: FALSE | AG25: FALSE | AI25: FALSE | AJ25: FALSE
A26: EMPAQPLAST_PROD | B26: OITM | C26: 1535248 | D26: BLen1Unit | E26: 90 | F26: 5 | G26: SMALLINT | H26: 445 | I26: 5 | J26: 0 | K26: TRUE | Q26: 73 | R26: INT | S26: 32 | T26: INVALID | U26: DEFAULT | V26: NONE | W26: 1535338 | X26: TRUE | Z26: FALSE | AA26: FALSE | AD26: DEFAULT | AF26: FALSE | AG26: FALSE | AI26: FALSE | AJ26: FALSE
A27: EMPAQPLAST_PROD | B27: OITM | C27: 1535248 | D27: BLen2Unit | E27: 92 | F27: 5 | G27: SMALLINT | H27: 458 | I27: 5 | J27: 0 | K27: TRUE | Q27: 73 | R27: INT | S27: 32 | T27: INVALID | U27: DEFAULT | V27: NONE | W27: 1535340 | X27: TRUE | Z27: FALSE | AA27: FALSE | AD27: DEFAULT | AF27: FALSE | AG27: FALSE | AI27: FALSE | AJ27: FALSE
A28: EMPAQPLAST_PROD | B28: OITM | C28: 1535248 | D28: BLength1 | E28: 89 | F28: 3 | G28: DECIMAL | H28: 435 | I28: 21 | J28: 6 | K28: TRUE | Q28: 66 | R28: FIXED | S28: 32 | T28: INVALID | U28: DEFAULT | V28: NONE | W28: 1535337 | X28: TRUE | Z28: FALSE | AA28: FALSE | AD28: DEFAULT | AF28: FALSE | AG28: FALSE | AI28: FALSE | AJ28: FALSE
A29: EMPAQPLAST_PROD | B29: OITM | C29: 1535248 | D29: Blength2 | E29: 91 | F29: 3 | G29: DECIMAL | H29: 448 | I29: 21 | J29: 6 | K29: TRUE | Q29: 66 | R29: FIXED | S29: 32 | T29: INVALID | U29: DEFAULT | V29: NONE | W29: 1535339 | X29: TRUE | Z29: FALSE | AA29: FALSE | AD29: DEFAULT | AF29: FALSE | AG29: FALSE | AI29: FALSE | AJ29: FALSE
A30: EMPAQPLAST_PROD | B30: OITM | C30: 1535248 | D30: BlncTrnsfr | E30: 46 | F30: -9 | G30: NVARCHAR | H30: 1568 | I30: 1 | K30: TRUE | L30: N | Q30: 83 | R30: STRING | S30: 32 | T30: INVALID | U30: DEFAULT | V30: NONE | W30: 1535294 | X30: TRUE | Z30: FALSE | AA30: FALSE | AD30: DEFAULT | AF30: FALSE | AG30: FALSE | AI30: FALSE | AJ30: FALSE
A31: EMPAQPLAST_PROD | B31: OITM | C31: 1535248 | D31: BlockOut | E31: 195 | F31: -9 | G31: NVARCHAR | H31: 1776 | I31: 1 | K31: TRUE | L31: Y | Q31: 83 | R31: STRING | S31: 32 | T31: INVALID | U31: DEFAULT | V31: NONE | W31: 1535443 | X31: TRUE | Z31: FALSE | AA31: FALSE | AD31: DEFAULT | AF31: FALSE | AG31: FALSE | AI31: FALSE | AJ31: FALSE
A32: EMPAQPLAST_PROD | B32: OITM | C32: 1535248 | D32: BuyUnitMsr | E32: 21 | F32: -9 | G32: NVARCHAR | H32: 1568 | I32: 100 | K32: TRUE | Q32: 83 | R32: STRING | S32: 32 | T32: INVALID | U32: DEFAULT | V32: NONE | W32: 1535269 | X32: TRUE | Z32: FALSE | AA32: FALSE | AD32: DEFAULT | AF32: FALSE | AG32: FALSE | AI32: FALSE | AJ32: FALSE
A33: EMPAQPLAST_PROD | B33: OITM | C33: 1535248 | D33: BVolume | E33: 93 | F33: 3 | G33: DECIMAL | H33: 461 | I33: 21 | J33: 6 | K33: TRUE | Q33: 66 | R33: FIXED | S33: 32 | T33: INVALID | U33: DEFAULT | V33: NONE | W33: 1535341 | X33: TRUE | Z33: FALSE | AA33: FALSE | AD33: DEFAULT | AF33: FALSE | AG33: FALSE | AI33: FALSE | AJ33: FALSE
A34: EMPAQPLAST_PROD | B34: OITM | C34: 1535248 | D34: BVolUnit | E34: 94 | F34: 5 | G34: SMALLINT | H34: 471 | I34: 5 | J34: 0 | K34: TRUE | Q34: 73 | R34: INT | S34: 32 | T34: INVALID | U34: DEFAULT | V34: NONE | W34: 1535342 | X34: TRUE | Z34: FALSE | AA34: FALSE | AD34: DEFAULT | AF34: FALSE | AG34: FALSE | AI34: FALSE | AJ34: FALSE
A35: EMPAQPLAST_PROD | B35: OITM | C35: 1535248 | D35: BWdth1Unit | E35: 86 | F35: 5 | G35: SMALLINT | H35: 419 | I35: 5 | J35: 0 | K35: TRUE | Q35: 73 | R35: INT | S35: 32 | T35: INVALID | U35: DEFAULT | V35: NONE | W35: 1535334 | X35: TRUE | Z35: FALSE | AA35: FALSE | AD35: DEFAULT | AF35: FALSE | AG35: FALSE | AI35: FALSE | AJ35: FALSE
A36: EMPAQPLAST_PROD | B36: OITM | C36: 1535248 | D36: BWdth2Unit | E36: 88 | F36: 5 | G36: SMALLINT | H36: 432 | I36: 5 | J36: 0 | K36: TRUE | Q36: 73 | R36: INT | S36: 32 | T36: INVALID | U36: DEFAULT | V36: NONE | W36: 1535336 | X36: TRUE | Z36: FALSE | AA36: FALSE | AD36: DEFAULT | AF36: FALSE | AG36: FALSE | AI36: FALSE | AJ36: FALSE
A37: EMPAQPLAST_PROD | B37: OITM | C37: 1535248 | D37: BWeight1 | E37: 95 | F37: 3 | G37: DECIMAL | H37: 474 | I37: 21 | J37: 6 | K37: TRUE | Q37: 66 | R37: FIXED | S37: 32 | T37: INVALID | U37: DEFAULT | V37: NONE | W37: 1535343 | X37: TRUE | Z37: FALSE | AA37: FALSE | AD37: DEFAULT | AF37: FALSE | AG37: FALSE | AI37: FALSE | AJ37: FALSE
A38: EMPAQPLAST_PROD | B38: OITM | C38: 1535248 | D38: BWeight2 | E38: 97 | F38: 3 | G38: DECIMAL | H38: 487 | I38: 21 | J38: 6 | K38: TRUE | Q38: 66 | R38: FIXED | S38: 32 | T38: INVALID | U38: DEFAULT | V38: NONE | W38: 1535345 | X38: TRUE | Z38: FALSE | AA38: FALSE | AD38: DEFAULT | AF38: FALSE | AG38: FALSE | AI38: FALSE | AJ38: FALSE
A39: EMPAQPLAST_PROD | B39: OITM | C39: 1535248 | D39: BWght1Unit | E39: 96 | F39: 5 | G39: SMALLINT | H39: 484 | I39: 5 | J39: 0 | K39: TRUE | Q39: 73 | R39: INT | S39: 32 | T39: INVALID | U39: DEFAULT | V39: NONE | W39: 1535344 | X39: TRUE | Z39: FALSE | AA39: FALSE | AD39: DEFAULT | AF39: FALSE | AG39: FALSE | AI39: FALSE | AJ39: FALSE
A40: EMPAQPLAST_PROD | B40: OITM | C40: 1535248 | D40: BWght2Unit | E40: 98 | F40: 5 | G40: SMALLINT | H40: 497 | I40: 5 | J40: 0 | K40: TRUE | Q40: 73 | R40: INT | S40: 32 | T40: INVALID | U40: DEFAULT | V40: NONE | W40: 1535346 | X40: TRUE | Z40: FALSE | AA40: FALSE | AD40: DEFAULT | AF40: FALSE | AG40: FALSE | AI40: FALSE | AJ40: FALSE
...

Sheet Diccionario Gobierno Datos
A1: Grupo de Articulos | B1: Entorno ERP | C1: Nombre de la tabla | D1: Nombre comun tabla | E1: Ubicación | F1: Responsable | G1: Nombre del campo | H1: responsable REGLAS | I1: Nombre comun campo | J1: Tipo Dato | K1: Tamaño | L1: Decimal | M1: Is Null | N1: Estado | O1: Fases | P1: Definición | Q1: reglas de perfilamiento | R1: Reglas de calidad | S1: Script Calidad | T1: Reglas de limpieza | U1: Política | V1: Crear Política | W1: Ejemplo | X1: MEDICIÓN DQ | Y1: AUTOMATIZACIÓN DE REGLAS EN HERRAMIENTA | Z1: CLEANNING
A2: Producto Terminado | B2: SAP B1 | C2: OITM | D2: Maestro de Articulos | E2: General | F2: Javier Cando, Carlos Barbosa, Ana Chacha, Mario Loachamin | G2: ItemCode | H2: Ana | I2: Codigo del Articulo | J2: =_xlfn.XLOOKUP(Fact_DicGobierno[[#This Row],[Nombre del campo]],'Inventario Campos OITM'!D:D,'Inventario Campos OITM'!G:G,0,0,1) -> NVARCHAR | K2: =_xlfn.XLOOKUP(Fact_DicGobierno[[#This Row],[Nombre del campo]],'Inventario Campos OITM'!D:D,'Inventario Campos OITM'!I:I,0,0,1) -> 50 | L2: =_xlfn.XLOOKUP(Fact_DicGobierno[[#This Row],[Nombre del campo]],'Inventario Campos OITM'!D:D,'Inventario Campos OITM'!J:J,0,0,1) -> 0 | M2: =_xlfn.XLOOKUP(Fact_DicGobierno[[#This Row],[Nombre del campo]],'Inventario Campos OITM'!D:D,'Inventario Campos OITM'!K:K,0,0,1) -> FALSE | N2: 2 - REGLAS | O2: P1 | P2: El campo corresponde al código del artículo. La estructura de dicho código varía según el grupo al que pertenezca el artículo: PT → Producto terminado y semi-elaborado(Lamina, Envase,Tapa,Botellas u otros) PTPR → Semielaborado(Preforma) SU - R - I → Repuestos MP → Materia prima AF → Activo fijo VA → Insumos y materiales | Q2: Codigo del articulo: Producto terminado y semi-elaborado debe empezar con PT, Seguido de la tabla de referencia de los TIPOS-ESPECIFICACIONES, Deben tener 4 caracteres seguido de PT excepto en preformas que solamente tiene 2 caracteres, Finalmente debe tener 4 digitos secuenciales excepto para preformas que tiene 6 digitos secuenciales | R2: Debe ser único, no nulo, cumplir la estructura definida según el grupo de artículo (PTPR, PTEPET, PTTAPA, PTBALD, PTLAMI, PTMANG, PTEPAD, PTFUN) en caso de ser un artículo de inmportación debe estar seguido de IMP. para ENVASES, TAPAS, MANIJAS , FUNDAS siguen 4 digitos consecutivos por cada grupo de artículo. En PREFORMAS los dos primeros dígitos corresponden al tipo de acabado de cuello precedidos por la letra C, en caso de ser tipo 2622 (VER TABLA DE REFERENCIA TIPO-ACABADO), seguido de 4 dígitos consecutivos. | S2: Transaction Notification propio de SAP | T2: NO APLICA ( en caso de tener un código errado , este debe ser obsoletado y se debe crear un nuevo código) | U2: N | V2: Si | W2: PTEPET0100 | X2: 0 | Y2: No | Z2: No
A3: Producto Terminado | B3: SAP B1 | C3: OITM | D3: Maestro de Articulos | E3: General | F3: Javier Cando, Carlos Barbosa, Ana Chacha, Mario Loachamin | G3: ItemName | H3: Ana | I3: Nombre del Articulo | J3: =_xlfn.XLOOKUP(Fact_DicGobierno[[#This Row],[Nombre del campo]],'Inventario Campos OITM'!D:D,'Inventario Campos OITM'!G:G,0,0,1) -> NVARCHAR | K3: =_xlfn.XLOOKUP(Fact_DicGobierno[[#This Row],[Nombre del campo]],'Inventario Campos OITM'!D:D,'Inventario Campos OITM'!I:I,0,0,1) -> 200 | L3: =_xlfn.XLOOKUP(Fact_DicGobierno[[#This Row],[Nombre del campo]],'Inventario Campos OITM'!D:D,'Inventario Campos OITM'!J:J,0,0,1) -> 0 | M3: =_xlfn.XLOOKUP(Fact_DicGobierno[[#This Row],[Nombre del campo]],'Inventario Campos OITM'!D:D,'Inventario Campos OITM'!K:K,0,0,1) -> TRUE | N3: 2 - REGLAS | O3: P1 | P3: El campo correponde al nombre, este nombre debe contener peso, tamaño, color | Q3: Lleno ,unico, nombre de tipo de producto ( ENVASE, TAPA,MANIJA .. ver tabla de referencia NOMBRE-TIPO-PRODUCTO, sin tilde, todo mayúsculas) siglas del material de fabricacion ( PEBD, PEAD , PET,MIX , PP ), especificación del producto( si existen números decimales se debe utilizar PUNTO ) | R3: No nulo. debe seguir la siguiente estructura= NOMBRE MATERIAL ESPECIFICACIONES . NOMBRE= Debe constar en la tabla de referencia (NOMBRE-TIPPO-PRODUCTO). MATERIAL= Debe constar en la lista sde materiales, y ser validado con la información de I+D. ESPECIFICACIONES = deben contener atributos descriptivos (peso, tamaño, color), con una longitud mínima recomendada: 5 caracteres, la información debe ser validada con I+D. | S3: Transaction Notification propio de SAP | T3: Revisar la información de I+D | U3: N | V3: Si | W3: ENVASE PET 400 ML CRISTAL JABON LIQUIDO DANEC 1881 | X3: 0 | Y3: No | Z3: No
A4: Producto Terminado | B4: SAP B1 | C4: OITM | D4: Maestro de Articulos | E4: General | F4: Javier Cando, Carlos Barbosa, Ana Chacha, Mario Loachamin | G4: U_Codigo_Secundario | H4: No aplica | I4: Codigo Secundario | J4: =_xlfn.XLOOKUP(Fact_DicGobierno[[#This Row],[Nombre del campo]],'Inventario Campos OITM'!D:D,'Inventario Campos OITM'!G:G,0,0,1) -> NVARCHAR | K4: =_xlfn.XLOOKUP(Fact_DicGobierno[[#This Row],[Nombre del campo]],'Inventario Campos OITM'!D:D,'Inventario Campos OITM'!I:I,0,0,1) -> 12 | L4: =_xlfn.XLOOKUP(Fact_DicGobierno[[#This Row],[Nombre del campo]],'Inventario Campos OITM'!D:D,'Inventario Campos OITM'!J:J,0,0,1) -> 0 | M4: =_xlfn.XLOOKUP(Fact_DicGobierno[[#This Row],[Nombre del campo]],'Inventario Campos OITM'!D:D,'Inventario Campos OITM'!K:K,0,0,1) -> TRUE | N4: 2 - REGLAS | O4: P1 | P4: El campo corresponde al codigo con el que lo conoce el cliente | Q4: Lleno / Vacío | R4: Puede estar vacío o lleno, pero si está lleno debe ser único y no duplicarse entre artículos. | S4: Transaction Notification propio de SAP | T4: N | U4: N | V4: Si | W4: D9690011001 | X4: 0 | Y4: No | Z4: No
A5: Producto Terminado | B5: SAP B1 | C5: OITM | D5: Maestro de Articulos | E5: General | F5: Javier Cando, Carlos Barbosa, Ana Chacha, Mario Loachamin | G5: FrgnName | H5: No aplica | I5: Nombre Extranjero | J5: =_xlfn.XLOOKUP(Fact_DicGobierno[[#This Row],[Nombre del campo]],'Inventario Campos OITM'!D:D,'Inventario Campos OITM'!G:G,0,0,1) -> NVARCHAR | K5: =_xlfn.XLOOKUP(Fact_DicGobierno[[#This Row],[Nombre del campo]],'Inventario Campos OITM'!D:D,'Inventario Campos OITM'!I:I,0,0,1) -> 200 | L5: =_xlfn.XLOOKUP(Fact_DicGobierno[[#This Row],[Nombre del campo]],'Inventario Campos OITM'!D:D,'Inventario Campos OITM'!J:J,0,0,1) -> 0 | M5: =_xlfn.XLOOKUP(Fact_DicGobierno[[#This Row],[Nombre del campo]],'Inventario Campos OITM'!D:D,'Inventario Campos OITM'!K:K,0,0,1) -> TRUE | N5: 2 - REGLAS | O5: P1 | P5: El campo corresponde al nombre con el que lo conoce el cliente | Q5: Lleno / Vacío | R5: Opcional. Si está lleno, debe diferenciarse de ItemName y mantener coherencia con cliente asignado. | S5: Transaction Notification propio de SAP | T5: N | U5: N | V5: Si | W5: BOT JABON LIQUIDO BEST 400 ML | X5: 0 | Y5: No | Z5: No
A6: Producto Terminado | B6: SAP B1 | C6: OITM | D6: Maestro de Articulos | E6: General | F6: Javier Cando, Carlos Barbosa, Ana Chacha, Mario Loachamin | G6: ItemType | H6: Ana | I6: Clase del Articulo | J6: =_xlfn.XLOOKUP(Fact_DicGobierno[[#This Row],[Nombre del campo]],'Inventario Campos OITM'!D:D,'Inventario Campos OITM'!G:G,0,0,1) -> NVARCHAR | K6: =_xlfn.XLOOKUP(Fact_DicGobierno[[#This Row],[Nombre del campo]],'Inventario Campos OITM'!D:D,'Inventario Campos OITM'!I:I,0,0,1) -> 1 | L6: =_xlfn.XLOOKUP(Fact_DicGobierno[[#This Row],[Nombre del campo]],'Inventario Campos OITM'!D:D,'Inventario Campos OITM'!J:J,0,0,1) -> 0 | M6: =_xlfn.XLOOKUP(Fact_DicGobierno[[#This Row],[Nombre del campo]],'Inventario Campos OITM'!D:D,'Inventario Campos OITM'!K:K,0,0,1) -> TRUE | N6: 2 - REGLAS | O6: P1 | P6: Clasificación del artículo: Material, Servicio u otro definido en SAP B1. | Q6: Deberá ir siempre la opción de ARTICULO | R6: No nulo. Para PT siempre debe ser ARTICULO | S6: Transaction Notification propio de SAP | T6: Cambiar a ARTICULO | U6: N | V6: Si | W6: Articulos | X6: 0 | Y6: No | Z6: No
A7: Producto Terminado | B7: SAP B1 | C7: OITM | D7: Maestro de Articulos | E7: General | F7: Javier Cando, Carlos Barbosa, Ana Chacha, Mario Loachamin | G7: ItmsGrpCod | H7: No aplica | I7: Grupo de Articulos | J7: =_xlfn.XLOOKUP(Fact_DicGobierno[[#This Row],[Nombre del campo]],'Inventario Campos OITM'!D:D,'Inventario Campos OITM'!G:G,0,0,1) -> SMALLINT | K7: =_xlfn.XLOOKUP(Fact_DicGobierno[[#This Row],[Nombre del campo]],'Inventario Campos OITM'!D:D,'Inventario Campos OITM'!I:I,0,0,1) -> 5 | L7: =_xlfn.XLOOKUP(Fact_DicGobierno[[#This Row],[Nombre del campo]],'Inventario Campos OITM'!D:D,'Inventario Campos OITM'!J:J,0,0,1) -> 0 | M7: =_xlfn.XLOOKUP(Fact_DicGobierno[[#This Row],[Nombre del campo]],'Inventario Campos OITM'!D:D,'Inventario Campos OITM'!K:K,0,0,1) -> TRUE | N7: 2 - REGLAS | O7: P1 | P7: Relación al grupo al que pertenece el artículo (referencia a tabla OITB). | Q7: Lleno | R7: No nulo. Debe existir en tabla OITB. Validar integridad referencial. | S7: Transaction Notification propio de SAP | T7: N | U7: N | V7: Si | W7: PRODUCTO TERMINADO | X7: 0 | Y7: No | Z7: No
A8: Producto Terminado | B8: SAP B1 | C8: OITM | D8: Maestro de Articulos | E8: General | F8: Javier Cando, Carlos Barbosa, Ana Chacha, Mario Loachamin | G8: UgpEntry | H8: Ana | I8: Grupo unid. de medida | J8: =_xlfn.XLOOKUP(Fact_DicGobierno[[#This Row],[Nombre del campo]],'Inventario Campos OITM'!D:D,'Inventario Campos OITM'!G:G,0,0,1) -> INTEGER | K8: =_xlfn.XLOOKUP(Fact_DicGobierno[[#This Row],[Nombre del campo]],'Inventario Campos OITM'!D:D,'Inventario Campos OITM'!I:I,0,0,1) -> 10 | L8: =_xlfn.XLOOKUP(Fact_DicGobierno[[#This Row],[Nombre del campo]],'Inventario Campos OITM'!D:D,'Inventario Campos OITM'!J:J,0,0,1) -> 0 | M8: =_xlfn.XLOOKUP(Fact_DicGobierno[[#This Row],[Nombre del campo]],'Inventario Campos OITM'!D:D,'Inventario Campos OITM'!K:K,0,0,1) -> TRUE | N8: 2 - REGLAS | O8: P1 | P8: Identificador del grupo de unidades de medida aplicable al artículo. | Q8: La unida de medida estará relacionada con el tipo de producto: ENVASES, TAPAS, MANIJAS, BALDES, PREFORMAS Y FUNDAS deben ir en unidades (UN) mientras que las LÁMINAS y MANGAS deberán ir en kilos (KG), el TIPO DE PRODUCTO DEBE CORRESPONDER A LA TABLA DE REFERENCIA NOMBRE-TIPO-PRODUCTO | R8: Revisar tabla de referencia (NOMBRE-TIPO-PRODUCTO), debe conincidir con el tipo de producto en el campo NOMBRE DEL ARTÍCULO | S8: Transaction Notification propio de SAP | T8: En caso de un dato errado, revisar el tipo del artículo, diponible en el campo Nombre Articulo y completar con UN o KG de acuerdo a la regla de perfilamiento. | U8: N | V8: Si | W8: UN | X8: 0 | Y8: No | Z8: No
A9: Producto Terminado | B9: SAP B1 | C9: OITM | D9: Maestro de Articulos | E9: General | F9: Javier Cando, Carlos Barbosa, Ana Chacha, Mario Loachamin | G9: InvntItem | H9: Mario | I9: Artículo de inventario | J9: =_xlfn.XLOOKUP(Fact_DicGobierno[[#This Row],[Nombre del campo]],'Inventario Campos OITM'!D:D,'Inventario Campos OITM'!G:G,0,0,1) -> NVARCHAR | K9: =_xlfn.XLOOKUP(Fact_DicGobierno[[#This Row],[Nombre del campo]],'Inventario Campos OITM'!D:D,'Inventario Campos OITM'!I:I,0,0,1) -> 1 | L9: =_xlfn.XLOOKUP(Fact_DicGobierno[[#This Row],[Nombre del campo]],'Inventario Campos OITM'!D:D,'Inventario Campos OITM'!J:J,0,0,1) -> 0 | M9: =_xlfn.XLOOKUP(Fact_DicGobierno[[#This Row],[Nombre del campo]],'Inventario Campos OITM'!D:D,'Inventario Campos OITM'!K:K,0,0,1) -> TRUE | N9: 2 - REGLAS | O9: P1 | P9: Indica si el artículo se gestiona con inventario (Y/N). | Q9: TODO PT TIENE Y | R9: Solo valores Y/N. No nulo. | S9: Transaction Notification propio de SAP | T9: En el caso de tener un dato erroneo debe ser remplazado por Y | U9: N | V9: Si | W9: Check | X9: 0 | Y9: No | Z9: No
A10: Producto Terminado | B10: SAP B1 | C10: OITM | D10: Maestro de Articulos | E10: General | F10: Javier Cando, Carlos Barbosa, Ana Chacha, Mario Loachamin | G10: SellItem | H10: Mario | I10: Artículo venta | J10: =_xlfn.XLOOKUP(Fact_DicGobierno[[#This Row],[Nombre del campo]],'Inventario Campos OITM'!D:D,'Inventario Campos OITM'!G:G,0,0,1) -> NVARCHAR | K10: =_xlfn.XLOOKUP(Fact_DicGobierno[[#This Row],[Nombre del campo]],'Inventario Campos OITM'!D:D,'Inventario Campos OITM'!I:I,0,0,1) -> 1 | L10: =_xlfn.XLOOKUP(Fact_DicGobierno[[#This Row],[Nombre del campo]],'Inventario Campos OITM'!D:D,'Inventario Campos OITM'!J:J,0,0,1) -> 0 | M10: =_xlfn.XLOOKUP(Fact_DicGobierno[[#This Row],[Nombre del campo]],'Inventario Campos OITM'!D:D,'Inventario Campos OITM'!K:K,0,0,1) -> TRUE | N10: 2 - REGLAS | O10: P1 | P10: Indica si el artículo está disponible para ventas (Y/N). | Q10: TODO PT TIENE Y | R10: No nulo. | S10: Transaction Notification propio de SAP | T10: En el caso de tener un dato erroneo debe ser remplazado por Y | U10: N | V10: Si | W10: Check | X10: 0 | Y10: No | Z10: No
A11: Producto Terminado | B11: SAP B1 | C11: OITM | D11: Maestro de Articulos | E11: General | F11: Javier Cando, Carlos Barbosa, Ana Chacha, Mario Loachamin | G11: PrchseItem | H11: Mario | I11: Artículo de compra | J11: =_xlfn.XLOOKUP(Fact_DicGobierno[[#This Row],[Nombre del campo]],'Inventario Campos OITM'!D:D,'Inventario Campos OITM'!G:G,0,0,1) -> NVARCHAR | K11: =_xlfn.XLOOKUP(Fact_DicGobierno[[#This Row],[Nombre del campo]],'Inventario Campos OITM'!D:D,'Inventario Campos OITM'!I:I,0,0,1) -> 1 | L11: =_xlfn.XLOOKUP(Fact_DicGobierno[[#This Row],[Nombre del campo]],'Inventario Campos OITM'!D:D,'Inventario Campos OITM'!J:J,0,0,1) -> 0 | M11: =_xlfn.XLOOKUP(Fact_DicGobierno[[#This Row],[Nombre del campo]],'Inventario Campos OITM'!D:D,'Inventario Campos OITM'!K:K,0,0,1) -> TRUE | N11: 2 - REGLAS | O11: P1 | P11: Indica si el artículo es COMPRA, VENTA o INVENTARIADO | Q11: Todo articulo que empice con PT debera tener el check de articulo de inventario y articulo de venta. En caso de ser un artículo importado también deberá tener el check de compras | R11: Debe tener siempre el Check de artículo de venta, artículo de inventario y en caso ser un artículo importado debe tener el check de compras. | S11: Transaction Notification propio de SAP | T11: Todo articulo PT se debe cambiar al check de articulo de venta y de inventario, se debe revisar que existan las siglas IMP en el código del producto, en caso de existir debe tener el check de compras. | U11: N | V11: Si | W11: Check | X11: 0 | Y11: No | Z11: No
A12: Producto Terminado | B12: SAP B1 | C12: OITM | D12: Maestro de Articulos | E12: General | F12: Javier Cando, Carlos Barbosa, Ana Chacha, Mario Loachamin | G12: PriceUnit | H12: Ana | I12: Unidad de determinación de precios | J12: =_xlfn.XLOOKUP(Fact_DicGobierno[[#This Row],[Nombre del campo]],'Inventario Campos OITM'!D:D,'Inventario Campos OITM'!G:G,0,0,1) -> INTEGER | K12: =_xlfn.XLOOKUP(Fact_DicGobierno[[#This Row],[Nombre del campo]],'Inventario Campos OITM'!D:D,'Inventario Campos OITM'!I:I,0,0,1) -> 10 | L12: =_xlfn.XLOOKUP(Fact_DicGobierno[[#This Row],[Nombre del campo]],'Inventario Campos OITM'!D:D,'Inventario Campos OITM'!J:J,0,0,1) -> 0 | M12: =_xlfn.XLOOKUP(Fact_DicGobierno[[#This Row],[Nombre del campo]],'Inventario Campos OITM'!D:D,'Inventario Campos OITM'!K:K,0,0,1) -> TRUE | N12: 2 - REGLAS | O12: P1 | P12: Unidad de medida utilizada para calcular los precios. | Q12: Siempre deberá ir MONEDA PRIMARIA | R12: No nulo. Se seleccionará la opción MONEDA PRIMARIA | S12: Transaction Notification propio de SAP | T12: Corregir con MONEDA PRIMARIA | U12: N | V12: Si | W12: UN | X12: 0 | Y12: No | Z12: No
A13: Producto Terminado | B13: SAP B1 | C13: OITM | D13: Maestro de Articulos | E13: General | F13: Javier Cando, Carlos Barbosa, Ana Chacha, Mario Loachamin | G13: WTLiable | H13: No aplica | I13: Sujeto a retención de impuesto | J13: =_xlfn.XLOOKUP(Fact_DicGobierno[[#This Row],[Nombre del campo]],'Inventario Campos OITM'!D:D,'Inventario Campos OITM'!G:G,0,0,1) -> NVARCHAR | K13: =_xlfn.XLOOKUP(Fact_DicGobierno[[#This Row],[Nombre del campo]],'Inventario Campos OITM'!D:D,'Inventario Campos OITM'!I:I,0,0,1) -> 1 | L13: =_xlfn.XLOOKUP(Fact_DicGobierno[[#This Row],[Nombre del campo]],'Inventario Campos OITM'!D:D,'Inventario Campos OITM'!J:J,0,0,1) -> 0 | M13: =_xlfn.XLOOKUP(Fact_DicGobierno[[#This Row],[Nombre del campo]],'Inventario Campos OITM'!D:D,'Inventario Campos OITM'!K:K,0,0,1) -> TRUE | N13: 2 - REGLAS | O13: P1 | P13: Marca si el artículo está sujeto a retenciones de impuestos (S/N). | Q13: Lleno / Vacío | R13: Solo valores Y/N. Consistencia con parametrización fiscal. | S13: Transaction Notification propio de SAP | T13: N | U13: N | V13: Si | W13: Check | X13: 0 | Y13: No | Z13: No
... A24: Producto Terminado | B24: SAP B1 | C24: OITM | D24: Maestro de Articulos | E24: Datos de planificación | F24: Javier Cando, Carlos Barbosa, Ana Chacha, Mario Loachamin | G24: PricingPrc | H24: Mario | I24: Método aprovisionamiento | J24: =_xlfn.XLOOKUP(Fact_DicGobierno[[#This Row],[Nombre del campo]],'Inventario Campos OITM'!D:D,'Inventario Campos OITM'!G:G,0,0,1) -> DECIMAL | K24: =_xlfn.XLOOKUP(Fact_DicGobierno[[#This Row],[Nombre del campo]],'Inventario Campos OITM'!D:D,'Inventario Campos OITM'!I:I,0,0,1) -> 21 | L24: =_xlfn.XLOOKUP(Fact_DicGobierno[[#This Row],[Nombre del campo]],'Inventario Campos OITM'!D:D,'Inventario Campos OITM'!J:J,0,0,1) -> 6 | M24: =_xlfn.XLOOKUP(Fact_DicGobierno[[#This Row],[Nombre del campo]],'Inventario Campos OITM'!D:D,'Inventario Campos OITM'!K:K,0,0,1) -> TRUE | N24: 2 - REGLAS | O24: P1 | P24: Indica si el artículo es producido o comprado. | Q24: Todo articulo PT que se vaya a producir debe ser llenado con EFECTUAR caso contrario debe tener Comprar si es articulo de Compra. | R24: Debe estar lleno con la opcion Efectuar si el articulo empieza con PT | S24: Transaction Notification propio de SAP | T24: En el caso de tener un dato erróneo , este se debe reemplazar con EFECTUAR | U24: N | V24: Si | W24: Efectuar | X24: 0 | Y24: No | Z24: No
A25: Producto Terminado | B25: SAP B1 | C25: OITM | D25: Maestro de Articulos | E25: Datos de planificación | F25: Javier Cando, Carlos Barbosa, Ana Chacha, Mario Loachamin | G25: LeadTime | H25: Carlos | I25: Tiempo lead | J25: =_xlfn.XLOOKUP(Fact_DicGobierno[[#This Row],[Nombre del campo]],'Inventario Campos OITM'!D:D,'Inventario Campos OITM'!G:G,0,0,1) -> INTEGER | K25: =_xlfn.XLOOKUP(Fact_DicGobierno[[#This Row],[Nombre del campo]],'Inventario Campos OITM'!D:D,'Inventario Campos OITM'!I:I,0,0,1) -> 10 | L25: =_xlfn.XLOOKUP(Fact_DicGobierno[[#This Row],[Nombre del campo]],'Inventario Campos OITM'!D:D,'Inventario Campos OITM'!J:J,0,0,1) -> 0 | M25: =_xlfn.XLOOKUP(Fact_DicGobierno[[#This Row],[Nombre del campo]],'Inventario Campos OITM'!D:D,'Inventario Campos OITM'!K:K,0,0,1) -> TRUE | N25: 2 - REGLAS | O25: P1 | P25: Tiempo estimado de entrega o producción (días). | Q25: Todo PT tiene un leadtime en días que depende del CICLO y la cantidad de unidades. | R25: Este campo debera ser lleno cun un número entre de 1 a 20 calculado en base al ciclo y cantidad de cada articulo que empiece con PT. | S25: Transaction Notification propio de SAP | T25: Validar que todo PT debe tener su lead time de 20 días | U25: N | V25: Si | W25: 30 | X25: 0 | Y25: No | Z25: No
A26: Producto Terminado | B26: SAP B1 | C26: OITM | D26: Maestro de Articulos | E26: Datos de planificación | F26: Javier Cando, Carlos Barbosa, Ana Chacha, Mario Loachamin | G26: ToleranDay | H26: Carlos | I26: Días de tolerancia | J26: =_xlfn.XLOOKUP(Fact_DicGobierno[[#This Row],[Nombre del campo]],'Inventario Campos OITM'!D:D,'Inventario Campos OITM'!G:G,0,0,1) -> INTEGER | K26: =_xlfn.XLOOKUP(Fact_DicGobierno[[#This Row],[Nombre del campo]],'Inventario Campos OITM'!D:D,'Inventario Campos OITM'!I:I,0,0,1) -> 10 | L26: =_xlfn.XLOOKUP(Fact_DicGobierno[[#This Row],[Nombre del campo]],'Inventario Campos OITM'!D:D,'Inventario Campos OITM'!J:J,0,0,1) -> 0 | M26: =_xlfn.XLOOKUP(Fact_DicGobierno[[#This Row],[Nombre del campo]],'Inventario Campos OITM'!D:D,'Inventario Campos OITM'!K:K,0,0,1) -> TRUE | N26: 2 - REGLAS | O26: P1 | P26: Días adicionales permitidos en la entrega o consumo del artículo. | Q26: Cantidad de días de tolerancia agregadas al lead time con un límite de 25 | R26: Este campo debera estar lleno con numeros enteros, NO DECIMALES, de 0 hasta 24 | S26: Transaction Notification propio de SAP | T26: Validar que cada parametro este lleno, si esta vacio o es erroneo colocar VALIDAR DIAS DE TOLERANCIA | U26: N | V26: Si | W26: 10 | X26: 0 | Y26: No | Z26: No
A27: Producto Terminado | B27: SAP B1 | C27: OITM | D27: Maestro de Articulos | E27: Propiedades | F27: Javier Cando, Carlos Barbosa, Ana Chacha, Mario Loachamin | G27: QryGroup1 | H27: Ana | I27: DANEC | J27: =_xlfn.XLOOKUP(Fact_DicGobierno[[#This Row],[Nombre del campo]],'Inventario Campos OITM'!D:D,'Inventario Campos OITM'!G:G,0,0,1) -> NVARCHAR | K27: =_xlfn.XLOOKUP(Fact_DicGobierno[[#This Row],[Nombre del campo]],'Inventario Campos OITM'!D:D,'Inventario Campos OITM'!I:I,0,0,1) -> 1 | L27: =_xlfn.XLOOKUP(Fact_DicGobierno[[#This Row],[Nombre del campo]],'Inventario Campos OITM'!D:D,'Inventario Campos OITM'!J:J,0,0,1) -> 0 | M27: =_xlfn.XLOOKUP(Fact_DicGobierno[[#This Row],[Nombre del campo]],'Inventario Campos OITM'!D:D,'Inventario Campos OITM'!K:K,0,0,1) -> TRUE | N27: 2 - REGLAS | O27: P1 | P27: Indicador de pertenencia al grupo comercial DANEC (marcado S/N). | Q27: Y solo si el PT pertenece a DANEC , caso contrario debe ser N | R27: Se debe observar en la tabla de referencia el tipo de cliente | S27: Transaction Notification propio de SAP | T27: Se debe observar en la tabla de referencia el tipo de cliente | U27: N | V27: Si | W27: Check | X27: 0 | Y27: No | Z27: No
A28: Producto Terminado | B28: SAP B1 | C28: OITM | D28: Maestro de Articulos | E28: Propiedades | F28: Javier Cando, Carlos Barbosa, Ana Chacha, Mario Loachamin | G28: QryGroup2 | H28: Ana | I28: TERRAFERTIL | J28: =_xlfn.XLOOKUP(Fact_DicGobierno[[#This Row],[Nombre del campo]],'Inventario Campos OITM'!D:D,'Inventario Campos OITM'!G:G,0,0,1) -> NVARCHAR | K28: =_xlfn.XLOOKUP(Fact_DicGobierno[[#This Row],[Nombre del campo]],'Inventario Campos OITM'!D:D,'Inventario Campos OITM'!I:I,0,0,1) -> 1 | L28: =_xlfn.XLOOKUP(Fact_DicGobierno[[#This Row],[Nombre del campo]],'Inventario Campos OITM'!D:D,'Inventario Campos OITM'!J:J,0,0,1) -> 0 | M28: =_xlfn.XLOOKUP(Fact_DicGobierno[[#This Row],[Nombre del campo]],'Inventario Campos OITM'!D:D,'Inventario Campos OITM'!K:K,0,0,1) -> TRUE | N28: 2 - REGLAS | O28: P1 | P28: Indicador de pertenencia al grupo comercial TERRAFERTIL (marcado S/N). | Q28: Y solo si el PT pertenece a TERRAFERTIL , caso contrario debe ser N | R28: Se debe observar en la tabla de referencia el tipo de cliente | S28: Transaction Notification propio de SAP | T28: Se debe observar en la tabla de referencia el tipo de cliente | U28: N | V28: Si | W28: Check | X28: 0 | Y28: No | Z28: No
A29: Producto Terminado | B29: BEAS MANUFACTURY | C29: OITM | D29: Maestro de Articulos | E29: Produccion Avanzada | F29: Javier Cando, Carlos Barbosa, Ana Chacha, Mario Loachamin | G29: U_beas_gruppe | H29: Mario | I29: Grupo de materiales | J29: =_xlfn.XLOOKUP(Fact_DicGobierno[[#This Row],[Nombre del campo]],'Inventario Campos OITM'!D:D,'Inventario Campos OITM'!G:G,0,0,1) -> NVARCHAR | K29: =_xlfn.XLOOKUP(Fact_DicGobierno[[#This Row],[Nombre del campo]],'Inventario Campos OITM'!D:D,'Inventario Campos OITM'!I:I,0,0,1) -> 20 | L29: =_xlfn.XLOOKUP(Fact_DicGobierno[[#This Row],[Nombre del campo]],'Inventario Campos OITM'!D:D,'Inventario Campos OITM'!J:J,0,0,1) -> 0 | M29: =_xlfn.XLOOKUP(Fact_DicGobierno[[#This Row],[Nombre del campo]],'Inventario Campos OITM'!D:D,'Inventario Campos OITM'!K:K,0,0,1) -> TRUE | N29: 2 - REGLAS | O29: P1 | P29: Clasificación del artículo dentro de Beas Manufacturing. | Q29: Todo articulo que empiece con PT se debe llenar con base a la SECCION/AREA del que pertenesca el PT creado. VER TABLA DE REFERENCIA GRUPO MATERIALES | R29: Debera estar lleno, segun al grupo de articulos que pertenece el PT, la información del material debe coincidir con el atributo Nombre Artículo. | S29: Transaction Notification propio de SAP | T29: En caso de tener un dato erróneo , este se debe reemplazar con la información del material disponible en el campo Nombre Artículo | U29: N | V29: Si | W29: SOP-PET | X29: 0 | Y29: No | Z29: No
A30: Producto Terminado | B30: BEAS MANUFACTURY | C30: OITM | D30: Maestro de Articulos | E30: Produccion Avanzada | F30: Javier Cando, Carlos Barbosa, Ana Chacha, Mario Loachamin | G30: U_beas_prccode | H30: Mario | I30: Centro de coste | J30: =_xlfn.XLOOKUP(Fact_DicGobierno[[#This Row],[Nombre del campo]],'Inventario Campos OITM'!D:D,'Inventario Campos OITM'!G:G,0,0,1) -> NVARCHAR | K30: =_xlfn.XLOOKUP(Fact_DicGobierno[[#This Row],[Nombre del campo]],'Inventario Campos OITM'!D:D,'Inventario Campos OITM'!I:I,0,0,1) -> 20 | L30: =_xlfn.XLOOKUP(Fact_DicGobierno[[#This Row],[Nombre del campo]],'Inventario Campos OITM'!D:D,'Inventario Campos OITM'!J:J,0,0,1) -> 0 | M30: =_xlfn.XLOOKUP(Fact_DicGobierno[[#This Row],[Nombre del campo]],'Inventario Campos OITM'!D:D,'Inventario Campos OITM'!K:K,0,0,1) -> TRUE | N30: 2 - REGLAS | O30: P1 | P30: Código de centro de coste asociado al artículo en Beas. | Q30: Todo articulo que empiece con PT debe tener el centro del costo igual al Grupo de Materiales y esto debera ser llenado con base a la SECCION/AREA del que pertenesca el PT creado. | R30: Debera estar lleno, segun al grupo de articulos que pertenece el PT, la información del material debe coincidir con el atributo Nombre Artículo. | S30: Transaction Notification propio de SAP | T30: En caso de tener un dato erróneo , este se debe reemplazar con la información del material disponible en el campo Nombre Artículo | U30: N | V30: Si | W30: SOP-PET | X30: 0 | Y30: No | Z30: No
A31: Producto Terminado | B31: BEAS MANUFACTURY | C31: OITM | D31: Maestro de Articulos | E31: Produccion Avanzada | F31: Javier Cando, Carlos Barbosa, Ana Chacha, Mario Loachamin | G31: U_beas_prodrelease | H31: Mario | I31: Liberado Producción | J31: =_xlfn.XLOOKUP(Fact_DicGobierno[[#This Row],[Nombre del campo]],'Inventario Campos OITM'!D:D,'Inventario Campos OITM'!G:G,0,0,1) -> NVARCHAR | K31: =_xlfn.XLOOKUP(Fact_DicGobierno[[#This Row],[Nombre del campo]],'Inventario Campos OITM'!D:D,'Inventario Campos OITM'!I:I,0,0,1) -> 1 | L31: =_xlfn.XLOOKUP(Fact_DicGobierno[[#This Row],[Nombre del campo]],'Inventario Campos OITM'!D:D,'Inventario Campos OITM'!J:J,0,0,1) -> 0 | M31: =_xlfn.XLOOKUP(Fact_DicGobierno[[#This Row],[Nombre del campo]],'Inventario Campos OITM'!D:D,'Inventario Campos OITM'!K:K,0,0,1) -> TRUE | N31: 2 - REGLAS | O31: P1 | P31: Define si el artículo está liberado para órdenes de producción (Y/N). | Q31: Todo articulo que empiece con PT debe estar con CHECK (Y) activado. | R31: debera estar lleno con el check de activado todo articulo que empiece con PT | S31: Transaction Notification propio de SAP | T31: En el caso de PT debe tener el check de liberado, en el caso que no empiece con PT debe ser nulo | U31: N | V31: Si | W31: Check | X31: 0 | Y31: No | Z31: No
A32: Producto Terminado | B32: BEAS MANUFACTURY | C32: OITM | D32: Maestro de Articulos | E32: Produccion Avanzada | F32: Javier Cando, Carlos Barbosa, Ana Chacha, Mario Loachamin | G32: U_beas_batchroh | H32: Mario | I32: Localización del Lote | J32: =_xlfn.XLOOKUP(Fact_DicGobierno[[#This Row],[Nombre del campo]],'Inventario Campos OITM'!D:D,'Inventario Campos OITM'!G:G,0,0,1) -> NVARCHAR | K32: =_xlfn.XLOOKUP(Fact_DicGobierno[[#This Row],[Nombre del campo]],'Inventario Campos OITM'!D:D,'Inventario Campos OITM'!I:I,0,0,1) -> 1 | L32: =_xlfn.XLOOKUP(Fact_DicGobierno[[#This Row],[Nombre del campo]],'Inventario Campos OITM'!D:D,'Inventario Campos OITM'!J:J,0,0,1) -> 0 | M32: =_xlfn.XLOOKUP(Fact_DicGobierno[[#This Row],[Nombre del campo]],'Inventario Campos OITM'!D:D,'Inventario Campos OITM'!K:K,0,0,1) -> TRUE | N32: 2 - REGLAS | O32: P1 | P32: Atributo que determina la localización del LOTE | Q32: Todo articulo que empiece con PT debe tener la DETERMINACION AUTOMATICA DE LOTE | R32: Debe estar lleno con la opcion DETERMINACION DE LOTE si el articulo empieza con PT. | S32: Transaction Notification propio de SAP | T32: En el caso de tener un dato erróneo , este se debe reemplazar con DETERMINACION DE LOTE | U32: N | V32: Si | W32: N | X32: 0 | Y32: No | Z32: No
A33: Producto Terminado | B33: SAP B1 | C33: OITM | D33: Maestro de Articulos | E33: Comentarios | F33: Javier Cando, Carlos Barbosa, Ana Chacha, Mario Loachamin | G33: PicturName | H33: Carlos | I33: Imagen del Articulo | J33: =_xlfn.XLOOKUP(Fact_DicGobierno[[#This Row],[Nombre del campo]],'Inventario Campos OITM'!D:D,'Inventario Campos OITM'!G:G,0,0,1) -> NVARCHAR | K33: =_xlfn.XLOOKUP(Fact_DicGobierno[[#This Row],[Nombre del campo]],'Inventario Campos OITM'!D:D,'Inventario Campos OITM'!I:I,0,0,1) -> 200 | L33: =_xlfn.XLOOKUP(Fact_DicGobierno[[#This Row],[Nombre del campo]],'Inventario Campos OITM'!D:D,'Inventario Campos OITM'!J:J,0,0,1) -> 0 | M33: =_xlfn.XLOOKUP(Fact_DicGobierno[[#This Row],[Nombre del campo]],'Inventario Campos OITM'!D:D,'Inventario Campos OITM'!K:K,0,0,1) -> TRUE | N33: 2 - REGLAS | O33: P1 | P33: Ruta o nombre del archivo de imagen asociado al artículo. | Q33: En todo articulo PT creado se debera adjuntar ruta como imagen de la ficha tecnica y de laminas del arte | R33: Debe estar LLENO, si el código del producto empieza con PTLAMI se debe adjuntar la ruta del arte en un archivo tipo (.jpg, .png), en otros casos debe ser la ruta de la fiucha técnica tipo .pdf , validar extensión de archivo (.jpg, .png,.pdf) y ruta accesible. La ruta válida debe ser \\192.168.20.18\SAP\Pictures\..... | S33: Transaction Notification propio de SAP | T33: Validar la información con Diseño Gráfico | U33: N | V33: Si | W33: \\192.168.20.18\SAP\Pictures | X33: 0 | Y33: No | Z33: No
A34: Producto Terminado | B34: BEAS MANUFACTURY | C34: OITM | D34: Maestro de Articulos | E34: Campos definidos por el usuario | F34: Javier Cando, Carlos Barbosa, Ana Chacha, Mario Loachamin | G34: U_beas_dispo | H34: Mario | I34: Exploción lista de materiales | J34: =_xlfn.XLOOKUP(Fact_DicGobierno[[#This Row],[Nombre del campo]],'Inventario Campos OITM'!D:D,'Inventario Campos OITM'!G:G,0,0,1) -> NVARCHAR | K34: =_xlfn.XLOOKUP(Fact_DicGobierno[[#This Row],[Nombre del campo]],'Inventario Campos OITM'!D:D,'Inventario Campos OITM'!I:I,0,0,1) -> 1 | L34: =_xlfn.XLOOKUP(Fact_DicGobierno[[#This Row],[Nombre del campo]],'Inventario Campos OITM'!D:D,'Inventario Campos OITM'!J:J,0,0,1) -> 0 | M34: =_xlfn.XLOOKUP(Fact_DicGobierno[[#This Row],[Nombre del campo]],'Inventario Campos OITM'!D:D,'Inventario Campos OITM'!K:K,0,0,1) -> TRUE | N34: 2 - REGLAS | O34: P1 | P34: Define la explosion de los articulos estos pueden ser: Por Orden, Orientado a Stock, Articulo Fantasma, No hay resolución. | Q34: Todo articulo que empiece con PT que en el grupo de articulos pertenesca a PRODUCTO TERMINADO debera ser llenado con la letra A y Todo articulo que empiece con PT que en el grupo de articulos pertenesca a PRODUCTO SEMIELABORADO debera ser llenado con la letra B | R34: Debe estar lleno, en caso de que el código del producto empiece con PT, y en el atributo de Grupo de Artículo, es PRODUCTO TERMINADO se completa con A, si es SEMIELABORADO se completa con B | S34: Transaction Notification propio de SAP | T34: Se debe cambiar con A si en el campo Grupo de articulos consta como PRODUCTO TERMINADO, y B si consta como PRODUCTO SEMIELABORADO. | U34: N | V34: Si | W34: Por Orden | X34: 0 | Y34: No | Z34: No
A35: Producto Terminado | B35: SAP B1 | C35: OITM | D35: Maestro de Articulos | E35: Campos definidos por el usuario | F35: Javier Cando, Carlos Barbosa, Ana Chacha, Mario Loachamin | G35: U_EMPA_ESPESOR | H35: Mauro | I35: Espesor | J35: =_xlfn.XLOOKUP(Fact_DicGobierno[[#This Row],[Nombre del campo]],'Inventario Campos OITM'!D:D,'Inventario Campos OITM'!G:G,0,0,1) -> DECIMAL | K35: =_xlfn.XLOOKUP(Fact_DicGobierno[[#This Row],[Nombre del campo]],'Inventario Campos OITM'!D:D,'Inventario Campos OITM'!I:I,0,0,1) -> 21 | L35: =_xlfn.XLOOKUP(Fact_DicGobierno[[#This Row],[Nombre del campo]],'Inventario Campos OITM'!D:D,'Inventario Campos OITM'!J:J,0,0,1) -> 6 | M35: =_xlfn.XLOOKUP(Fact_DicGobierno[[#This Row],[Nombre del campo]],'Inventario Campos OITM'!D:D,'Inventario Campos OITM'!K:K,0,0,1) -> TRUE | N35: 2 - REGLAS | O35: P1 | P35: Este campo es caracteristica de Lamina | Q35: LLENAR EL CAMPO UNICAMENTE CUANDO EL PRODUCTO SEA PTLAMI Y PTMANG es numérico en micras sin decimales | R35: Debe estar lleno cuando el articulo sea PTLAMI y PTMANG, deben ser numeros enteros desde 25 UM hasta 125 UM , La unidad del micraje debera ser UM Despues del numero entero. | S35: Transaction Notification propio de SAP | T35: Revisar la información de I+D | U35: N | V35: Si | W35: 12 | X35: 0 | Y35: No | Z35: No
A36: Producto Terminado | B36: SAP B1 | C36: OITM | D36: Maestro de Articulos | E36: Campos definidos por el usuario | F36: Javier Cando, Carlos Barbosa, Ana Chacha, Mario Loachamin | G36: U_EMPA_DESIDAD | H36: Mauro | I36: Densidad | J36: =_xlfn.XLOOKUP(Fact_DicGobierno[[#This Row],[Nombre del campo]],'Inventario Campos OITM'!D:D,'Inventario Campos OITM'!G:G,0,0,1) -> DECIMAL | K36: =_xlfn.XLOOKUP(Fact_DicGobierno[[#This Row],[Nombre del campo]],'Inventario Campos OITM'!D:D,'Inventario Campos OITM'!I:I,0,0,1) -> 21 | L36: =_xlfn.XLOOKUP(Fact_DicGobierno[[#This Row],[Nombre del campo]],'Inventario Campos OITM'!D:D,'Inventario Campos OITM'!J:J,0,0,1) -> 6 | M36: =_xlfn.XLOOKUP(Fact_DicGobierno[[#This Row],[Nombre del campo]],'Inventario Campos OITM'!D:D,'Inventario Campos OITM'!K:K,0,0,1) -> TRUE | N36: 2 - REGLAS | O36: P1 | P36: Este campo es caracteristica de Lamina | Q36: LLENAR EL CAMPO UNICAMENTE CUANDO EL PRODUCTO SEA PTLAMI Y PTMANG ,VER TABLA DE REFERENCIA DE DENSIDAD DE LA MP. | R36: Debe estar lleno cuando el articulo sea PTLAMI y PTMANG, solo se acepta la información de la tabla de referencia de densidad de la MP | S36: Transaction Notification propio de SAP | T36: En caso de PTLAMI y PTMANG se debe llenar mediante la tabla de referencia de MP, en otro caso se debe remplazar por el nulo. | U36: N | V36: Si | W36: 13 | X36: 0 | Y36: No | Z36: No
A37: Producto Terminado | B37: SAP B1 | C37: OITM | D37: Maestro de Articulos | E37: Campos definidos por el usuario | F37: Javier Cando, Carlos Barbosa, Ana Chacha, Mario Loachamin | G37: U_EMPA_ANCHO | H37: Mauro | I37: Ancho | J37: =_xlfn.XLOOKUP(Fact_DicGobierno[[#This Row],[Nombre del campo]],'Inventario Campos OITM'!D:D,'Inventario Campos OITM'!G:G,0,0,1) -> DECIMAL | K37: =_xlfn.XLOOKUP(Fact_DicGobierno[[#This Row],[Nombre del campo]],'Inventario Campos OITM'!D:D,'Inventario Campos OITM'!I:I,0,0,1) -> 21 | L37: =_xlfn.XLOOKUP(Fact_DicGobierno[[#This Row],[Nombre del campo]],'Inventario Campos OITM'!D:D,'Inventario Campos OITM'!J:J,0,0,1) -> 6 | M37: =_xlfn.XLOOKUP(Fact_DicGobierno[[#This Row],[Nombre del campo]],'Inventario Campos OITM'!D:D,'Inventario Campos OITM'!K:K,0,0,1) -> TRUE | N37: 2 - REGLAS | O37: P1 | P37: Este campo es caracteristica de Lamina | Q37: LLENAR EL CAMPO UNICAMENTE CUANDO EL PRODUCTO SEA PTLAMI Y PTMANG es numérico en centimetro con un decimal | R37: Debe estar lleno cuando el articulo creado sea PTLAMI Y PTMANG. En el caso de PTLAMI sera en cm desde 8.4 cm hasta 120 cm , en el caso de PTMANG sera en pulgadas desde 5 " hasta 58 " | S37: Transaction Notification propio de SAP | T37: Revisar la información de I+D | U37: N | V37: Si | W37: 10 | X37: 0 | Y37: No | Z37: No
A38: Producto Terminado | B38: SAP B1 | C38: OITM | D38: Maestro de Articulos | E38: Campos definidos por el usuario | F38: Javier Cando, Carlos Barbosa, Ana Chacha, Mario Loachamin | G38: U_PLG_CICLE | H38: Mario | I38: Ciclo | J38: =_xlfn.XLOOKUP(Fact_DicGobierno[[#This Row],[Nombre del campo]],'Inventario Campos OITM'!D:D,'Inventario Campos OITM'!G:G,0,0,1) -> DECIMAL | K38: =_xlfn.XLOOKUP(Fact_DicGobierno[[#This Row],[Nombre del campo]],'Inventario Campos OITM'!D:D,'Inventario Campos OITM'!I:I,0,0,1) -> 21 | L38: =_xlfn.XLOOKUP(Fact_DicGobierno[[#This Row],[Nombre del campo]],'Inventario Campos OITM'!D:D,'Inventario Campos OITM'!J:J,0,0,1) -> 6 | M38: =_xlfn.XLOOKUP(Fact_DicGobierno[[#This Row],[Nombre del campo]],'Inventario Campos OITM'!D:D,'Inventario Campos OITM'!K:K,0,0,1) -> TRUE | N38: 2 - REGLAS | O38: P1 | P38: Ciclo de producción de cada producto, y respresenta la cantidad de segundos que toma producir el número total de las cavidades de un molde. Este campo es un factor de calculo de receta de todos los productos menos de LAMINAS, MANGAS y FUNDAS | Q38: Llenar el campo numerico en segundos, con 2 decimales cuando se cree el PT, con base a las especificaciones del productos. En el caso de laminas, mangas y fundas debe estar vacio. | R38: Debe estar lleno en el caso de PT en caso de laminas, mangas y fundas debe estar vacío. EN CASO DE PT debe ser completado con valores desde 1.00 hasta un máximo 160.00 segundos | S38: Transaction Notification propio de SAP | T38: En caso de Láminas PT LAMI, mangas PTMANG y fundas PTFUN, se debe reemplazar cualquier dato por el nulo. En otro caso la información debe ser validada con la de I+D. | U38: N | V38: Si | W38: 20.00 | X38: 0 | Y38: No | Z38: No
A39: Producto Terminado | B39: SAP B1 | C39: OITM | D39: Maestro de Articulos | E39: Campos definidos por el usuario | F39: Javier Cando, Carlos Barbosa, Ana Chacha, Mario Loachamin | G39: U_EMPA_CARACTERISTICA_TIPO | H39: Ana | I39: Caracteristica Tipo | J39: =_xlfn.XLOOKUP(Fact_DicGobierno[[#This Row],[Nombre del campo]],'Inventario Campos OITM'!D:D,'Inventario Campos OITM'!G:G,0,0,1) -> NVARCHAR | K39: =_xlfn.XLOOKUP(Fact_DicGobierno[[#This Row],[Nombre del campo]],'Inventario Campos OITM'!D:D,'Inventario Campos OITM'!I:I,0,0,1) -> 50 | L39: =_xlfn.XLOOKUP(Fact_DicGobierno[[#This Row],[Nombre del campo]],'Inventario Campos OITM'!D:D,'Inventario Campos OITM'!J:J,0,0,1) -> 0 | M39: =_xlfn.XLOOKUP(Fact_DicGobierno[[#This Row],[Nombre del campo]],'Inventario Campos OITM'!D:D,'Inventario Campos OITM'!K:K,0,0,1) -> FALSE | N39: 2 - REGLAS | O39: P1 | P39: Este campo identifica si el producto es de un cliente o generico | Q39: Este dependerá de la DESCRIPCIÓN DE ARTICULO, si el mismo lleva el nombre del cliente sera ESPECIFICO caso contrario GENÉRICO | R39: No nulo, solo consta con los valores ESPECIFICO, GENERICO de acuerdo al campo Nombre del artículo, VER TABLA DE REFERENCIA CLIENTES ESPECIFICOS | S39: Transaction Notification propio de SAP | T39: En caso d un dato errado revisar el campo nombre artículo, si este tiene un cliente dentro de la tabla de referencia CLIENTES ESPECIFICOS se cambiará por ESPECIFICO, en caso de no tener cliente e se ambiará por GENERICO | U39: N | V39: Si | W39: Generico / Personalizado | X39: 0 | Y39: No | Z39: No
A40: Producto Terminado | B40: SAP B1 | C40: OITM | D40: Maestro de Articulos | E40: Campos definidos por el usuario | F40: Javier Cando, Carlos Barbosa, Ana Chacha, Mario Loachamin | G40: U_EMPA_CARACTERISTICA_MP | H40: Ana | I40: Caracteristica Tipo MP | J40: =_xlfn.XLOOKUP(Fact_DicGobierno[[#This Row],[Nombre del campo]],'Inventario Campos OITM'!D:D,'Inventario Campos OITM'!G:G,0,0,1) -> NVARCHAR | K40: =_xlfn.XLOOKUP(Fact_DicGobierno[[#This Row],[Nombre del campo]],'Inventario Campos OITM'!D:D,'Inventario Campos OITM'!I:I,0,0,1) -> 50 | L40: =_xlfn.XLOOKUP(Fact_DicGobierno[[#This Row],[Nombre del campo]],'Inventario Campos OITM'!D:D,'Inventario Campos OITM'!J:J,0,0,1) -> 0 | M40: =_xlfn.XLOOKUP(Fact_DicGobierno[[#This Row],[Nombre del campo]],'Inventario Campos OITM'!D:D,'Inventario Campos OITM'!K:K,0,0,1) -> TRUE | N40: 2 - REGLAS | O40: P1 | P40: Este campo define con que tipo de materia prima se esta elaborando o produciendo | Q40: Este dependerá del campo Nombre Articulo, si el mismo lleva PEDB, PEAD, PET, PET + PCR, o PP | R40: Se debe tener como referencia la descripción del nombre para colocar el tipo de MP | S40: Transaction Notification propio de SAP | T40: N | U40: N | V40: Si | W40: PET+PCR | X40: 0 | Y40: No | Z40: No

Sheet Listas
A1: etapa | B1: estado | C1: estadoLlave
A2: 0 | B2: POR DEFINIR | C2: =+tbl_estadoAtributo[[#This Row],[etapa]]&" - "&tbl_estadoAtributo[[#This Row],[estado]] -> 0 - POR DEFINIR
A3: 1 | B3: DEFINICIONES | C3: =+tbl_estadoAtributo[[#This Row],[etapa]]&" - "&tbl_estadoAtributo[[#This Row],[estado]] -> 1 - DEFINICIONES
A4: 2 | B4: REGLAS | C4: =+tbl_estadoAtributo[[#This Row],[etapa]]&" - "&tbl_estadoAtributo[[#This Row],[estado]] -> 2 - REGLAS
A5: 3 | B5: POLÍTICA | C5: =+tbl_estadoAtributo[[#This Row],[etapa]]&" - "&tbl_estadoAtributo[[#This Row],[estado]] -> 3 - POLÍTICA
A6: 4 | B6: MEDICIÓN DQ | C6: =+tbl_estadoAtributo[[#This Row],[etapa]]&" - "&tbl_estadoAtributo[[#This Row],[estado]] -> 4 - MEDICIÓN DQ
A7: 5 | B7: REGLAS GD | C7: =+tbl_estadoAtributo[[#This Row],[etapa]]&" - "&tbl_estadoAtributo[[#This Row],[estado]] -> 5 - REGLAS GD
A8: 6 | B8: AUTOM. REGLAS | C8: =+tbl_estadoAtributo[[#This Row],[etapa]]&" - "&tbl_estadoAtributo[[#This Row],[estado]] -> 6 - AUTOM. REGLAS
A9: 7 | B9: CLEANNING | C9: =+tbl_estadoAtributo[[#This Row],[etapa]]&" - "&tbl_estadoAtributo[[#This Row],[estado]] -> 7 - CLEANNING
A10: 8 | B10: GOBERNADO | C10: =+tbl_estadoAtributo[[#This Row],[etapa]]&" - "&tbl_estadoAtributo[[#This Row],[estado]] -> 8 - GOBERNADO

Sheet Actividades
A1: Semana 1
A2: Actividad | B2: Responsable
A3: Solicitar apoyo a Contaduría para conseguir API de conección con datos para clientes | B3: Gustavo León y Diego Vallejo
A4: Asegurar coneción de API con módilo de creación de clientes en JDE. | B4: Diego Vallejo
A5: Cruce de datos en SingleStore vs CSV SRI. | B5: David Montalvo
A6: Actualización de campos | B6: William Tito
A8: Semana 2
A9: Actividad | B9: Responsable
A10: Verificar de los clientes grandes actuales, quienes requieren que se les facture con una razón social diferente a la registrada en el SRI. Ej: PRONACA | B10: Gustavo León
A11: Consultar qué | B11: David Montalvo
A13: Semana 3
A14: Actividad | B14: Responsable
A15: Congelar AsIs. Validar flujo actual del proceso de creación y actualización de datos para maestro de Clientes. | B15: Gustavo León
A16: Definir alcance de To Be: Sobre el proceso AsIs, definir qué se necesita cambiar para mejorar el proceso, ya sea con PowerStreet o Gobernanza de Datos. Data Owner propone el cambio como doliente del proceso y se valida con el comité los alcances a los que se puede llegar. | B16: Gustavo León
A17: Reunión para socializar campos de categorías y conocer cómo se utilizan. | B17: Diego Vallejo
A18: Probar API gratuita para obtener campos de País, Ciudad y Provincia en base a Georeferenciación. | B18: David Montalvo
A19: Levantar API para extracción de datos desde información del SRI. Se busca que esta API trabaje dentro de JDE o SS para asegurar que los campos Nombre de Cliente (ABALPH) y Dirección (ALADD1) se alimenten de lo registrado en el SRI para clientes que cuenten con RUC. | B19: David Montalvo
A20: Crear ticket en TI para introducir API con SRI a JDE. La API debe trabajar sobre el módulo de validación de nuevos clientes que maneja Crédito y Cobranza. | B20: Yaser Ronquillo
A23: Semana 4 S1
A24: Actividad | B24: Responsable
A25: Traer ejemplo de política de gobernanza para revisar el formato. Debe ser sencilla. | B25: Yaser Ronquillo
A26: Buscar reunión en esta semana con IT para aplicación de las APIs | B26: Yaser Ronquillo
A27: Verificar API de GEO para traer Ciudad y Provincia | B27: David Montalvo
A28: Reunirse para explorar el flujo de toma de decisiones de la API Geo y SRI | B28: David Montalvo y Diego Vallejo

Sheet Guía Reglas
A1: Reglas de Perfilamiento de Datos | C1: Reglas de Calidad de Datos
A3: 1. Distribución de Longitud: | C3: 1. Formato de Teléfono:
A5: Regla: La longitud de los valores en el campo "Teléfono" debe ser consistente. | C5: Regla: Los números de teléfono deben cumplir con un formato estándar específico.
A6: Ejemplo: El perfilamiento puede revelar que la longitud de los números de teléfono varía entre 8 a 15 dígitos, indicando que hay inconsistencias en el formato. | C6: Ejemplo: El campo "Teléfono" debe seguir el formato de 10 dígitos (sin guiones ni espacios), por ejemplo, "1234567890". Alternativamente, podría seguir un formato internacional estándar como "+1-123-456-7890".
A8: 2. Formato de Valores: | C8: 2. Validez de Números:
A10: Regla: Los números de teléfono deben seguir un patrón específico. | C10: Regla: Los números de teléfono deben ser válidos y existentes.
